[I 19:26:20.261 NotebookApp] [nb_conda_kernels] enabled, 12 kernels found
[I 19:26:20.654 NotebookApp] Authentication of /metrics is OFF, since other authentication is disabled.
[W 19:26:23.583 NotebookApp] All authentication is disabled.  Anyone who can connect to this server will be able to run code.
[W 2023-02-21 19:26:28.009 LabApp] Config option `kernel_spec_manager_class` not recognized by `LabApp`.
[W 2023-02-21 19:26:28.014 LabApp] 'ip' has moved from NotebookApp to ServerApp. This config will be passed to ServerApp. Be sure to update your config before our next release.
[W 2023-02-21 19:26:28.014 LabApp] 'port' has moved from NotebookApp to ServerApp. This config will be passed to ServerApp. Be sure to update your config before our next release.
[W 2023-02-21 19:26:28.015 LabApp] 'token' has moved from NotebookApp to ServerApp. This config will be passed to ServerApp. Be sure to update your config before our next release.
[W 2023-02-21 19:26:28.015 LabApp] 'password' has moved from NotebookApp to ServerApp. This config will be passed to ServerApp. Be sure to update your config before our next release.
[W 2023-02-21 19:26:28.015 LabApp] 'password' has moved from NotebookApp to ServerApp. This config will be passed to ServerApp. Be sure to update your config before our next release.
[W 2023-02-21 19:26:28.015 LabApp] 'password' has moved from NotebookApp to ServerApp. This config will be passed to ServerApp. Be sure to update your config before our next release.
[W 2023-02-21 19:26:28.016 LabApp] Config option `kernel_spec_manager_class` not recognized by `LabApp`.
[W 2023-02-21 19:26:28.026 LabApp] Config option `kernel_spec_manager_class` not recognized by `LabApp`.
[I 2023-02-21 19:26:28.028 LabApp] JupyterLab extension loaded from /om/user/leokoz8/envs/add_RL/lib/python3.8/site-packages/jupyterlab
[I 2023-02-21 19:26:28.028 LabApp] JupyterLab application directory is /om/user/leokoz8/envs/add_RL/share/jupyter/lab
[I 19:26:28.034 NotebookApp] Serving notebooks from local directory: /rdma/vast-rdma/vast/fiete/leokoz8/code/add_RL
[I 19:26:28.034 NotebookApp] Jupyter Notebook 6.3.0 is running at:
[I 19:26:28.034 NotebookApp] http://node060.cm.cluster:9000/
[I 19:26:28.034 NotebookApp] Use Control-C to stop this server and shut down all kernels (twice to skip confirmation).
[I 19:29:12.138 NotebookApp] 302 GET / (172.16.24.254) 8.990000ms
/om/user/leokoz8/envs/add_RL/lib/python3.8/json/encoder.py:257: UserWarning: date_default is deprecated since jupyter_client 7.0.0. Use jupyter_client.jsonutil.json_default.
  return _iterencode(o, 0)
[W 19:29:34.889 NotebookApp] Notebook notebooks/test_nb.ipynb is not trusted
Exception in callback <TaskWakeupMethWrapper object at 0x2ac92ea78430>(<Future finis...late\r\n\r\n'>)
handle: <Handle <TaskWakeupMethWrapper object at 0x2ac92ea78430>(<Future finis...late\r\n\r\n'>)>
Traceback (most recent call last):
  File "/om/user/leokoz8/envs/add_RL/lib/python3.8/asyncio/events.py", line 81, in _run
    self._context.run(self._callback, *self._args)
RuntimeError: Cannot enter into task <Task pending name='Task-10' coro=<HTTP1ServerConnection._server_request_loop() running at /om/user/leokoz8/envs/add_RL/lib/python3.8/site-packages/tornado/http1connection.py:825> wait_for=<Future finished result=b'GET /api/co...flate\r\n\r\n'> cb=[IOLoop.add_future.<locals>.<lambda>() at /om/user/leokoz8/envs/add_RL/lib/python3.8/site-packages/tornado/ioloop.py:687]> while another task <Task pending name='Task-2' coro=<KernelManager._async_start_kernel() running at /om/user/leokoz8/envs/add_RL/lib/python3.8/site-packages/jupyter_client/manager.py:71>> is being executed.
[I 19:29:35.923 NotebookApp] Kernel started: 3c891aa1-43d9-4228-b635-a5cbad9a2625, name: conda-env-leokoz8-add_RL-py
/om/user/leokoz8/envs/add_RL/lib/python3.8/json/encoder.py:257: UserWarning: date_default is deprecated since jupyter_client 7.0.0. Use jupyter_client.jsonutil.json_default.
  return _iterencode(o, 0)
[I 19:31:36.278 NotebookApp] Saving file at /notebooks/test_nb.ipynb
[W 19:31:36.289 NotebookApp] Notebook notebooks/test_nb.ipynb is not trusted
[I 19:33:35.667 NotebookApp] Saving file at /notebooks/test_nb.ipynb
[W 19:33:35.681 NotebookApp] Notebook notebooks/test_nb.ipynb is not trusted
[I 19:33:44.116 NotebookApp] Saving file at /notebooks/test_nb.ipynb
[W 19:33:44.117 NotebookApp] Notebook notebooks/test_nb.ipynb is not trusted
[I 19:35:35.659 NotebookApp] Saving file at /notebooks/test_nb.ipynb
[W 19:35:35.660 NotebookApp] Notebook notebooks/test_nb.ipynb is not trusted
[I 19:37:35.653 NotebookApp] Saving file at /notebooks/test_nb.ipynb
[W 19:37:35.654 NotebookApp] Notebook notebooks/test_nb.ipynb is not trusted
[I 19:39:35.668 NotebookApp] Saving file at /notebooks/test_nb.ipynb
[W 19:39:35.669 NotebookApp] Notebook notebooks/test_nb.ipynb is not trusted
[I 19:41:35.696 NotebookApp] Saving file at /notebooks/test_nb.ipynb
[W 19:41:35.696 NotebookApp] Notebook notebooks/test_nb.ipynb is not trusted
[I 19:43:35.658 NotebookApp] Saving file at /notebooks/test_nb.ipynb
[W 19:43:35.659 NotebookApp] Notebook notebooks/test_nb.ipynb is not trusted
[I 19:45:35.659 NotebookApp] Saving file at /notebooks/test_nb.ipynb
[W 19:45:35.660 NotebookApp] Notebook notebooks/test_nb.ipynb is not trusted
[I 19:47:35.662 NotebookApp] Saving file at /notebooks/test_nb.ipynb
[W 19:47:35.663 NotebookApp] Notebook notebooks/test_nb.ipynb is not trusted
Exception in callback <TaskStepMethWrapper object at 0x2ac92ea691f0>()
handle: <Handle <TaskStepMethWrapper object at 0x2ac92ea691f0>()>
Traceback (most recent call last):
  File "/om/user/leokoz8/envs/add_RL/lib/python3.8/asyncio/events.py", line 81, in _run
    self._context.run(self._callback, *self._args)
RuntimeError: Cannot enter into task <Task pending name='Task-12' coro=<HTTP1ServerConnection._server_request_loop() running at /om/user/leokoz8/envs/add_RL/lib/python3.8/site-packages/tornado/http1connection.py:842> cb=[IOLoop.add_future.<locals>.<lambda>() at /om/user/leokoz8/envs/add_RL/lib/python3.8/site-packages/tornado/ioloop.py:687]> while another task <Task pending name='Task-1830' coro=<PeriodicCallback._run() running at /om/user/leokoz8/envs/add_RL/lib/python3.8/site-packages/tornado/ioloop.py:921> cb=[IOLoop.add_future.<locals>.<lambda>() at /om/user/leokoz8/envs/add_RL/lib/python3.8/site-packages/tornado/ioloop.py:694]> is being executed.
[I 19:51:35.760 NotebookApp] Saving file at /notebooks/test_nb.ipynb
[W 19:51:35.780 NotebookApp] Notebook notebooks/test_nb.ipynb is not trusted
[I 19:53:35.673 NotebookApp] Saving file at /notebooks/test_nb.ipynb
[W 19:53:35.673 NotebookApp] Notebook notebooks/test_nb.ipynb is not trusted
[I 19:55:35.681 NotebookApp] Saving file at /notebooks/test_nb.ipynb
[W 19:55:35.682 NotebookApp] Notebook notebooks/test_nb.ipynb is not trusted
[I 19:57:35.662 NotebookApp] Saving file at /notebooks/test_nb.ipynb
[W 19:57:35.663 NotebookApp] Notebook notebooks/test_nb.ipynb is not trusted
[I 19:59:35.670 NotebookApp] Saving file at /notebooks/test_nb.ipynb
[W 19:59:35.684 NotebookApp] Notebook notebooks/test_nb.ipynb is not trusted
[I 20:01:35.673 NotebookApp] Saving file at /notebooks/test_nb.ipynb
[W 20:01:35.674 NotebookApp] Notebook notebooks/test_nb.ipynb is not trusted
[I 20:02:52.400 NotebookApp] Saving file at /notebooks/test_nb.ipynb
[W 20:02:52.401 NotebookApp] Notebook notebooks/test_nb.ipynb is not trusted
[I 20:03:35.667 NotebookApp] Saving file at /notebooks/test_nb.ipynb
[W 20:03:35.668 NotebookApp] Notebook notebooks/test_nb.ipynb is not trusted
[I 20:05:36.290 NotebookApp] Saving file at /notebooks/test_nb.ipynb
[W 20:05:36.291 NotebookApp] Notebook notebooks/test_nb.ipynb is not trusted
[I 20:07:35.672 NotebookApp] Saving file at /notebooks/test_nb.ipynb
[W 20:07:35.673 NotebookApp] Notebook notebooks/test_nb.ipynb is not trusted
[I 20:07:41.703 NotebookApp] Saving file at /notebooks/test_nb.ipynb
[W 20:07:41.703 NotebookApp] Notebook notebooks/test_nb.ipynb is not trusted
[I 20:07:43.168 NotebookApp] Starting buffering for 3c891aa1-43d9-4228-b635-a5cbad9a2625:870d245eee53442c851b356150d65644
slurmstepd: error: *** JOB 29473585 ON node060 CANCELLED AT 2023-02-21T20:08:02 ***
